Traceback (most recent call last):
  File "/Users/sah2249/miniconda3/envs/stat-methods-course/lib/python3.11/site-packages/jupyter_cache/executors/utils.py", line 58, in single_nb_execution
    executenb(
  File "/Users/sah2249/miniconda3/envs/stat-methods-course/lib/python3.11/site-packages/nbclient/client.py", line 1305, in execute
    return NotebookClient(nb=nb, resources=resources, km=km, **kwargs).execute()
           ^^^^^^^^^^^^^^^^^^^^^^^^^^^^^^^^^^^^^^^^^^^^^^^^^^^^^^^^^^^^^^^^^^^^^
  File "/Users/sah2249/miniconda3/envs/stat-methods-course/lib/python3.11/site-packages/jupyter_core/utils/__init__.py", line 166, in wrapped
    return loop.run_until_complete(inner)
           ^^^^^^^^^^^^^^^^^^^^^^^^^^^^^^
  File "/Users/sah2249/miniconda3/envs/stat-methods-course/lib/python3.11/asyncio/base_events.py", line 653, in run_until_complete
    return future.result()
           ^^^^^^^^^^^^^^^
  File "/Users/sah2249/miniconda3/envs/stat-methods-course/lib/python3.11/site-packages/nbclient/client.py", line 705, in async_execute
    await self.async_execute_cell(
  File "/Users/sah2249/miniconda3/envs/stat-methods-course/lib/python3.11/site-packages/nbclient/client.py", line 1058, in async_execute_cell
    await self._check_raise_for_error(cell, cell_index, exec_reply)
  File "/Users/sah2249/miniconda3/envs/stat-methods-course/lib/python3.11/site-packages/nbclient/client.py", line 914, in _check_raise_for_error
    raise CellExecutionError.from_cell_and_msg(cell, exec_reply_content)
nbclient.exceptions.CellExecutionError: An error occurred while executing the following cell:
------------------
# Load the file from disk if you haven't already.
import netCDF4
ds_nc4  = netCDF4.Dataset("../data/central-park-station-data.nc", "r")

plt.plot(ds_nc4["time"][:], ds_nc4["temp_avg"][:], linewidth=0.5)
------------------


[0;31m---------------------------------------------------------------------------[0m
[0;31mFileNotFoundError[0m                         Traceback (most recent call last)
Cell [0;32mIn[7], line 3[0m
[1;32m      1[0m [38;5;66;03m# Load the file from disk if you haven't already.[39;00m
[1;32m      2[0m [38;5;28;01mimport[39;00m [38;5;21;01mnetCDF4[39;00m
[0;32m----> 3[0m ds_nc4  [38;5;241m=[39m [43mnetCDF4[49m[38;5;241;43m.[39;49m[43mDataset[49m[43m([49m[38;5;124;43m"[39;49m[38;5;124;43m../data/central-park-station-data.nc[39;49m[38;5;124;43m"[39;49m[43m,[49m[43m [49m[38;5;124;43m"[39;49m[38;5;124;43mr[39;49m[38;5;124;43m"[39;49m[43m)[49m
[1;32m      5[0m plt[38;5;241m.[39mplot(ds_nc4[[38;5;124m"[39m[38;5;124mtime[39m[38;5;124m"[39m][:], ds_nc4[[38;5;124m"[39m[38;5;124mtemp_avg[39m[38;5;124m"[39m][:], linewidth[38;5;241m=[39m[38;5;241m0.5[39m)

File [0;32msrc/netCDF4/_netCDF4.pyx:2464[0m, in [0;36mnetCDF4._netCDF4.Dataset.__init__[0;34m()[0m

File [0;32msrc/netCDF4/_netCDF4.pyx:2027[0m, in [0;36mnetCDF4._netCDF4._ensure_nc_success[0;34m()[0m

[0;31mFileNotFoundError[0m: [Errno 2] No such file or directory: '../data/central-park-station-data.nc'

